Workbook

Sheet Setup Guide
A1: SETUP GUIDE
A2: Complete these steps before you start logging. Takes 30–60 minutes once. Skipping any step weakens the system.
A4: Step 1 | B4: Name your channels
B5: Replace 'Channel 1', 'Channel 2', 'Channel 3' with your actual channel names throughout this workbook: • Daily Log column D dropdown (right-click cell → Data Validation → edit list) • Dashboard rows 12–14 and 25–27 (column A) • Weekly Review section headers • Metrics tab section headers Rule: Max 3 active channels. 4 is the hard ceiling. Past that, none get enough pressure.
A6: Step 2 | B6: Define each channel
B7: In the Reference tab, fill in the Channel Taxonomy for each channel: • One-sentence channel definition (what does 'flowing' look like once it connects?) • 5–8 specific dig activities that produce artifacts • 4–6 specific drift activities — the ones that feel like work but don't deepen the channel The drift list is more important than the dig list. Be honest.
A8: Step 3 | B8: Set your breakthrough markers
B9: In the Metrics tab, replace the placeholder breakthrough markers with your own. These must be specific, pre-defined thresholds — not vague aspirations. Example: '100 weekly active users sustained over 4 weeks' not 'lots of users'. Without markers, you cannot recognize when dig-mode should end. Define them now.
A10: Step 4 | B10: Customize the reward menu
B11: In the Rewards tab, replace the placeholder reward names with things you actually want. Keep the three-tier structure (Recovery / Investment / Experience) and the currency split. Recovery rewards are priced in Points only. Investment rewards are priced in Digs only. Experience rewards require both currencies. Adjust prices after 4 weeks of real data — not before.
A12: Step 5 | B12: Define your gain actions
B13: In the Reference tab, list specific actions that qualify for each gain category: • Physical Gain: e.g. 45-min workout, 5km run, yoga session, meal prep • Mental Gain: e.g. deliberate vocabulary study, reading a nonfiction chapter with notes • Spiritual Gain: e.g. morning prayer, scripture reading, fasting, worship Vague categories get gamed. Specific lists don't.
A14: Step 6 | B14: Define your artifact types
B15: In the Artifacts tab, the artifact type dropdown has generic entries. Update it to match your channels (right-click any cell in column C → Data Validation). Examples: for a product channel: 'Feature Shipped', 'User Conversation', 'Distribution Experiment' For a trading channel: 'Trade Logged', 'Backtest Run', 'Log Review', 'Risk Rule Update'
A16: Step 7 | B16: Log your first week without optimizing
B17: Start logging. Every event, as it happens — not reconstructed at end of day. Don't change point values, reward prices, or channel definitions during week one. Goal of week one: build the logging habit and calibrate your intuition for dig vs drift. You will notice drift you were previously blind to. That noticing is the point.
A18: Step 8 | B18: Tune at week four
B19: After four weeks of real data, revisit: • Are the point values producing a meaningful weekly total? (Target: 100–150 pts / good week) • Are the reward prices reachable but not trivial? • Do the channel floors feel sustainable? • Are drift patterns repeating in your Weekly Reviews? Make calibration adjustments here, not in week one.

Sheet Dashboard
A1: DASHBOARD
A2: Check this daily. All numbers update automatically from Daily Log and Rewards.
A4: CURRENT BALANCES
A5: Total Points Earned | B5: =SUMIF('Daily Log'!K6:K205,">0",'Daily Log'!K6:K205) -> 0 | C5: Points Spent | D5: =SUM(Rewards!E19:E118) -> 0 | E5: POINT BALANCE | F5: =B5-D5 -> 0
A6: Total Digs Earned | B6: =SUMIF('Daily Log'!L6:L205,">0",'Daily Log'!L6:L205) -> 0 | C6: Digs Spent | D6: =SUM(Rewards!F19:F118) -> 0 | E6: DIG BALANCE | F6: =B6-D6 -> 0
A8: THIS WEEK
A9: Today | B9: =TODAY() -> 46152 | C9: Week # | D9: =WEEKNUM(TODAY(),21) -> 19 | E9: Year | F9: =YEAR(TODAY()) -> 2026
A11: Channel | B11: Digs This Week | C11: Points This Week | D11: Last Dig Date | E11: Days Since Last Dig
A12: Channel 1 | B12: =SUMPRODUCT(('Daily Log'!D6:D205=A12)*(IFERROR(WEEKNUM('Daily Log'!A6:A205,21),0)=$D$9)*(IFERROR(YEAR('Daily Log'!A6:A205),0)=$F$9)*'Daily Log'!L6:L205) -> 0 | C12: =SUMPRODUCT(('Daily Log'!D6:D205=A12)*(IFERROR(WEEKNUM('Daily Log'!A6:A205,21),0)=$D$9)*(IFERROR(YEAR('Daily Log'!A6:A205),0)=$F$9)*'Daily Log'!K6:K205) -> 0 | D12: =IFERROR(maxifs('Daily Log'!A6:A205,'Daily Log'!D6:D205,A12,'Daily Log'!C6:C205,"Dig Block"),"") -> 0 | E12: =IF(D12="","",TODAY()-D12) -> 46152
A13: Channel 2 | B13: =SUMPRODUCT(('Daily Log'!D6:D205=A13)*(IFERROR(WEEKNUM('Daily Log'!A6:A205,21),0)=$D$9)*(IFERROR(YEAR('Daily Log'!A6:A205),0)=$F$9)*'Daily Log'!L6:L205) -> 0 | C13: =SUMPRODUCT(('Daily Log'!D6:D205=A13)*(IFERROR(WEEKNUM('Daily Log'!A6:A205,21),0)=$D$9)*(IFERROR(YEAR('Daily Log'!A6:A205),0)=$F$9)*'Daily Log'!K6:K205) -> 0 | D13: =IFERROR(maxifs('Daily Log'!A6:A205,'Daily Log'!D6:D205,A13,'Daily Log'!C6:C205,"Dig Block"),"") -> 0 | E13: =IF(D13="","",TODAY()-D13) -> 46152
A14: Channel 3 | B14: =SUMPRODUCT(('Daily Log'!D6:D205=A14)*(IFERROR(WEEKNUM('Daily Log'!A6:A205,21),0)=$D$9)*(IFERROR(YEAR('Daily Log'!A6:A205),0)=$F$9)*'Daily Log'!L6:L205) -> 0 | C14: =SUMPRODUCT(('Daily Log'!D6:D205=A14)*(IFERROR(WEEKNUM('Daily Log'!A6:A205,21),0)=$D$9)*(IFERROR(YEAR('Daily Log'!A6:A205),0)=$F$9)*'Daily Log'!K6:K205) -> 0 | D14: =IFERROR(maxifs('Daily Log'!A6:A205,'Daily Log'!D6:D205,A14,'Daily Log'!C6:C205,"Dig Block"),"") -> 0 | E14: =IF(D14="","",TODAY()-D14) -> 46152
A16: ACTIVE BOOSTS (last 24 hours)
A17: Category | B17: Last Activation | C17: Hours Since | D17: Status
A18: Physical | B18: =IFERROR(maxifs('Daily Log'!A6:A205,'Daily Log'!C6:C205,"Gain Action",'Daily Log'!G6:G205,A18),"") -> 0 | C18: =IF(B18="","",ROUND((TODAY()-B18)*24,0)) -> 1107648 | D18: =IF(B18="","READY",IF(C18<24,"ACTIVE","READY")) -> READY
A19: Mental | B19: =IFERROR(maxifs('Daily Log'!A6:A205,'Daily Log'!C6:C205,"Gain Action",'Daily Log'!G6:G205,A19),"") -> 0 | C19: =IF(B19="","",ROUND((TODAY()-B19)*24,0)) -> 1107648 | D19: =IF(B19="","READY",IF(C19<24,"ACTIVE","READY")) -> READY
A20: Spiritual | B20: =IFERROR(maxifs('Daily Log'!A6:A205,'Daily Log'!C6:C205,"Gain Action",'Daily Log'!G6:G205,A20),"") -> 0 | C20: =IF(B20="","",ROUND((TODAY()-B20)*24,0)) -> 1107648 | D20: =IF(B20="","READY",IF(C20<24,"ACTIVE","READY")) -> READY
A22: TODAY'S FLOOR CHECK
A23: Minimum: 1 full dig per channel you've committed to today. Rotate 2 channels per day across the week.
A24: Channel | B24: Today's Digs | C24: Floor Met?
A25: Channel 1 | B25: =SUMPRODUCT(('Daily Log'!A6:A205=TODAY())*('Daily Log'!D6:D205=A25)*'Daily Log'!L6:L205) -> 0 | C25: =IF(B25>=1,"✓ Met","Not yet") -> Not yet
A26: Channel 2 | B26: =SUMPRODUCT(('Daily Log'!A6:A205=TODAY())*('Daily Log'!D6:D205=A26)*'Daily Log'!L6:L205) -> 0 | C26: =IF(B26>=1,"✓ Met","Not yet") -> Not yet
A27: Channel 3 | B27: =SUMPRODUCT(('Daily Log'!A6:A205=TODAY())*('Daily Log'!D6:D205=A27)*'Daily Log'!L6:L205) -> 0 | C27: =IF(B27>=1,"✓ Met","Not yet") -> Not yet

Sheet Daily Log
A1: DAILY LOG
A2: One row per event. Log in real time — end-of-day reconstruction is unreliable. Base Points, Final Points, and Digs calculate automatically. You only enter: Date, Time, Type, Channel, Duration, Artifact (Yes/Half/No/N/A), Boost Category, Boost Multiplier, and Notes.
A4: Date | B4: Time | C4: Type | D4: Channel | E4: Duration (min) | F4: Artifact | G4: Boost Category | H4: Boost Multiplier | I4: Notes | J4: Base Points | K4: Final Points | L4: Digs
A5: yyyy-mm-dd | B5: hh:mm | C5: ← dropdown | D5: ← dropdown | E5: e.g. 90 | F5: ← dropdown | G5: ← dropdown | H5: 1 / 1.5 / 2 / 2.5 | I5: Brief note on what you worked on / artifact produced | J5: auto | K5: auto | L5: auto
H6: 1 | J6: =IF(C6="",0,IF(AND(C6="Dig Block",F6="Yes"),10,IF(AND(C6="Dig Block",F6="Half"),5,IF(AND(C6="Dig Block",F6="No"),5,IF(C6="Extracurricular",5,IF(C6="Gain Action",8,IF(C6="Day Job",0,IF(C6="Boost Activation",0,0)))))))) -> 0 | K6: =IF(C6="",0,J6*H6) -> 0 | L6: =IF(C6="",0,IF(AND(C6="Dig Block",F6="Yes"),1,IF(AND(C6="Dig Block",F6="Half"),0.5,0))) -> 0
H7: 1 | J7: =IF(C7="",0,IF(AND(C7="Dig Block",F7="Yes"),10,IF(AND(C7="Dig Block",F7="Half"),5,IF(AND(C7="Dig Block",F7="No"),5,IF(C7="Extracurricular",5,IF(C7="Gain Action",8,IF(C7="Day Job",0,IF(C7="Boost Activation",0,0)))))))) -> 0 | K7: =IF(C7="",0,J7*H7) -> 0 | L7: =IF(C7="",0,IF(AND(C7="Dig Block",F7="Yes"),1,IF(AND(C7="Dig Block",F7="Half"),0.5,0))) -> 0
H8: 1 | J8: =IF(C8="",0,IF(AND(C8="Dig Block",F8="Yes"),10,IF(AND(C8="Dig Block",F8="Half"),5,IF(AND(C8="Dig Block",F8="No"),5,IF(C8="Extracurricular",5,IF(C8="Gain Action",8,IF(C8="Day Job",0,IF(C8="Boost Activation",0,0)))))))) -> 0 | K8: =IF(C8="",0,J8*H8) -> 0 | L8: =IF(C8="",0,IF(AND(C8="Dig Block",F8="Yes"),1,IF(AND(C8="Dig Block",F8="Half"),0.5,0))) -> 0
H9: 1 | J9: =IF(C9="",0,IF(AND(C9="Dig Block",F9="Yes"),10,IF(AND(C9="Dig Block",F9="Half"),5,IF(AND(C9="Dig Block",F9="No"),5,IF(C9="Extracurricular",5,IF(C9="Gain Action",8,IF(C9="Day Job",0,IF(C9="Boost Activation",0,0)))))))) -> 0 | K9: =IF(C9="",0,J9*H9) -> 0 | L9: =IF(C9="",0,IF(AND(C9="Dig Block",F9="Yes"),1,IF(AND(C9="Dig Block",F9="Half"),0.5,0))) -> 0
H10: 1 | J10: =IF(C10="",0,IF(AND(C10="Dig Block",F10="Yes"),10,IF(AND(C10="Dig Block",F10="Half"),5,IF(AND(C10="Dig Block",F10="No"),5,IF(C10="Extracurricular",5,IF(C10="Gain Action",8,IF(C10="Day Job",0,IF(C10="Boost Activation",0,0)))))))) -> 0 | K10: =IF(C10="",0,J10*H10) -> 0 | L10: =IF(C10="",0,IF(AND(C10="Dig Block",F10="Yes"),1,IF(AND(C10="Dig Block",F10="Half"),0.5,0))) -> 0
H11: 1 | J11: =IF(C11="",0,IF(AND(C11="Dig Block",F11="Yes"),10,IF(AND(C11="Dig Block",F11="Half"),5,IF(AND(C11="Dig Block",F11="No"),5,IF(C11="Extracurricular",5,IF(C11="Gain Action",8,IF(C11="Day Job",0,IF(C11="Boost Activation",0,0)))))))) -> 0 | K11: =IF(C11="",0,J11*H11) -> 0 | L11: =IF(C11="",0,IF(AND(C11="Dig Block",F11="Yes"),1,IF(AND(C11="Dig Block",F11="Half"),0.5,0))) -> 0
H12: 1 | J12: =IF(C12="",0,IF(AND(C12="Dig Block",F12="Yes"),10,IF(AND(C12="Dig Block",F12="Half"),5,IF(AND(C12="Dig Block",F12="No"),5,IF(C12="Extracurricular",5,IF(C12="Gain Action",8,IF(C12="Day Job",0,IF(C12="Boost Activation",0,0)))))))) -> 0 | K12: =IF(C12="",0,J12*H12) -> 0 | L12: =IF(C12="",0,IF(AND(C12="Dig Block",F12="Yes"),1,IF(AND(C12="Dig Block",F12="Half"),0.5,0))) -> 0
H13: 1 | J13: =IF(C13="",0,IF(AND(C13="Dig Block",F13="Yes"),10,IF(AND(C13="Dig Block",F13="Half"),5,IF(AND(C13="Dig Block",F13="No"),5,IF(C13="Extracurricular",5,IF(C13="Gain Action",8,IF(C13="Day Job",0,IF(C13="Boost Activation",0,0)))))))) -> 0 | K13: =IF(C13="",0,J13*H13) -> 0 | L13: =IF(C13="",0,IF(AND(C13="Dig Block",F13="Yes"),1,IF(AND(C13="Dig Block",F13="Half"),0.5,0))) -> 0
H14: 1 | J14: =IF(C14="",0,IF(AND(C14="Dig Block",F14="Yes"),10,IF(AND(C14="Dig Block",F14="Half"),5,IF(AND(C14="Dig Block",F14="No"),5,IF(C14="Extracurricular",5,IF(C14="Gain Action",8,IF(C14="Day Job",0,IF(C14="Boost Activation",0,0)))))))) -> 0 | K14: =IF(C14="",0,J14*H14) -> 0 | L14: =IF(C14="",0,IF(AND(C14="Dig Block",F14="Yes"),1,IF(AND(C14="Dig Block",F14="Half"),0.5,0))) -> 0
H15: 1 | J15: =IF(C15="",0,IF(AND(C15="Dig Block",F15="Yes"),10,IF(AND(C15="Dig Block",F15="Half"),5,IF(AND(C15="Dig Block",F15="No"),5,IF(C15="Extracurricular",5,IF(C15="Gain Action",8,IF(C15="Day Job",0,IF(C15="Boost Activation",0,0)))))))) -> 0 | K15: =IF(C15="",0,J15*H15) -> 0 | L15: =IF(C15="",0,IF(AND(C15="Dig Block",F15="Yes"),1,IF(AND(C15="Dig Block",F15="Half"),0.5,0))) -> 0
H16: 1 | J16: =IF(C16="",0,IF(AND(C16="Dig Block",F16="Yes"),10,IF(AND(C16="Dig Block",F16="Half"),5,IF(AND(C16="Dig Block",F16="No"),5,IF(C16="Extracurricular",5,IF(C16="Gain Action",8,IF(C16="Day Job",0,IF(C16="Boost Activation",0,0)))))))) -> 0 | K16: =IF(C16="",0,J16*H16) -> 0 | L16: =IF(C16="",0,IF(AND(C16="Dig Block",F16="Yes"),1,IF(AND(C16="Dig Block",F16="Half"),0.5,0))) -> 0
H17: 1 | J17: =IF(C17="",0,IF(AND(C17="Dig Block",F17="Yes"),10,IF(AND(C17="Dig Block",F17="Half"),5,IF(AND(C17="Dig Block",F17="No"),5,IF(C17="Extracurricular",5,IF(C17="Gain Action",8,IF(C17="Day Job",0,IF(C17="Boost Activation",0,0)))))))) -> 0 | K17: =IF(C17="",0,J17*H17) -> 0 | L17: =IF(C17="",0,IF(AND(C17="Dig Block",F17="Yes"),1,IF(AND(C17="Dig Block",F17="Half"),0.5,0))) -> 0
... H205: 1 | J205: =IF(C205="",0,IF(AND(C205="Dig Block",F205="Yes"),10,IF(AND(C205="Dig Block",F205="Half"),5,IF(AND(C205="Dig Block",F205="No"),5,IF(C205="Extracurricular",5,IF(C205="Gain Action",8,IF(C205="Day Job",0,IF(C205="Boost Activation",0,0)))))))) -> 0 | K205: =IF(C205="",0,J205*H205) -> 0 | L205: =IF(C205="",0,IF(AND(C205="Dig Block",F205="Yes"),1,IF(AND(C205="Dig Block",F205="Half"),0.5,0))) -> 0

Sheet Artifacts
A1: ARTIFACTS
A2: Log every substantial artifact here — one row per output. This becomes your portfolio over time. Look back through it quarterly. Replace the artifact types below with ones that match your channels.
A4: Date | B4: Channel | C4: Artifact Type | D4: Description | E4: Link / Reference | F4: Notes

Sheet Weekly Review
A1: WEEKLY REVIEW
A2: Every Sunday evening. 30–45 minutes. Three questions per channel + cross-cutting. Auto-pulls this week's totals.
A4: Week # | B4: Year | C4: Date Range | D4: Total Digs | E4: Total Points | F4: Notes
A5: =WEEKNUM(TODAY(),21) -> 19 | B5: =YEAR(TODAY()) -> 2026 | C5: =TEXT(TODAY()-WEEKDAY(TODAY(),3),"mmm d") & " – " & TEXT(TODAY()-WEEKDAY(TODAY(),3)+6,"mmm d") -> May 4 – May 10 | D5: =SUM(Dashboard!B12:B14) -> 0 | E5: =SUM(Dashboard!C12:C14) -> 0 | F5: ← This week's snapshot
A8: Channel 1 — WEEKLY REVIEW
A9: 1. Did the channel get deeper this week? Name a concrete artifact as evidence — not a feeling.
A10: 2. What activity was high-input but low-depth? (Find the leak — it's always there.)
A11: 3. What is the ONE highest-leverage dig for next week? Singular.
A12: 4. Leading metrics check — are the weekly activity counts on track?
A13: 5. Drift moments noticed this week (be honest):
A17: Channel 2 — WEEKLY REVIEW
A18: 1. Did the channel get deeper this week? Name a concrete artifact as evidence — not a feeling.
A19: 2. What activity was high-input but low-depth? (Find the leak — it's always there.)
A20: 3. What is the ONE highest-leverage dig for next week? Singular.
A21: 4. Leading metrics check — are the weekly activity counts on track?
A22: 5. Drift moments noticed this week (be honest):
... A39: Anything to adjust in next week's structure or channel rotation?

Sheet Metrics
A1: CHANNEL METRICS
A2: Update monthly. Replace the placeholder metric names with ones specific to your channels. Leading = activity counts you control (weekly). Lagging = outcome indicators (monthly). Breakthrough markers = pre-defined thresholds where dig-mode ends and flow-mode begins.
A4: Channel 1
A5: LEADING METRICS (weekly)
A6: Metric | B6: Type | C6: Last Month | D6: This Month | E6: Δ | F6: Target / Notes | G6: Source
A7: [Define your primary leading metric — something you produce weekly] | B7: count | E7: =IFERROR(D7-C7,"") -> 0
A8: [Define a second leading metric — e.g. conversations, outputs, experiments] | B8: count | E8: =IFERROR(D8-C8,"") -> 0
A9: [Define a third leading metric — ideally something distribution-related] | B9: count | E9: =IFERROR(D9-C9,"") -> 0
A10: [Define a fourth leading metric — optional] | B10: trend | E10: =IFERROR(D10-C10,"") -> 0
A11: LAGGING METRICS (monthly)
A12: Metric | B12: Type | C12: Last Month | D12: This Month | E12: Δ | F12: Target / Notes | G12: Source
A13: [Define your primary lagging metric — the outcome this channel is building toward] | B13: count/trend | E13: =IFERROR(D13-C13,"") -> 0
A14: [Define a second lagging metric — e.g. revenue, rate, audience size] | B14: count | E14: =IFERROR(D14-C14,"") -> 0
A15: [Define a third lagging metric] | B15: trend | E15: =IFERROR(D15-C15,"") -> 0
A16: [Define a fourth lagging metric — optional] | B16: count | E16: =IFERROR(D16-C16,"") -> 0
A17: BREAKTHROUGH MARKERS
A18: Marker | B18: Hit? | C18: Date Hit | D18: Notes
A19: [First breakthrough marker — the earliest signal the channel has connected] | B19: No
A20: [Second breakthrough marker — a stronger confirmation of flow] | B20: No
A21: [Third breakthrough marker — the threshold you'd consider flow-mode achieved] | B21: No
A22: [Fourth marker — optional stretch target] | B22: No
A25: Channel 2
A26: LEADING METRICS (weekly)
A27: Metric | B27: Type | C27: Last Month | D27: This Month | E27: Δ | F27: Target / Notes | G27: Source
A28: [Define your primary leading metric — something you produce weekly] | B28: count | E28: =IFERROR(D28-C28,"") -> 0
A29: [Define a second leading metric — e.g. conversations, outputs, experiments] | B29: count | E29: =IFERROR(D29-C29,"") -> 0
A30: [Define a third leading metric — ideally something distribution-related] | B30: count | E30: =IFERROR(D30-C30,"") -> 0
A31: [Define a fourth leading metric — optional] | B31: trend | E31: =IFERROR(D31-C31,"") -> 0
A32: LAGGING METRICS (monthly)
A33: Metric | B33: Type | C33: Last Month | D33: This Month | E33: Δ | F33: Target / Notes | G33: Source
A34: [Define your primary lagging metric — the outcome this channel is building toward] | B34: count/trend | E34: =IFERROR(D34-C34,"") -> 0
A35: [Define a second lagging metric — e.g. revenue, rate, audience size] | B35: count | E35: =IFERROR(D35-C35,"") -> 0
A36: [Define a third lagging metric] | B36: trend | E36: =IFERROR(D36-C36,"") -> 0
A37: [Define a fourth lagging metric — optional] | B37: count | E37: =IFERROR(D37-C37,"") -> 0
A38: BREAKTHROUGH MARKERS
A39: Marker | B39: Hit? | C39: Date Hit | D39: Notes
A40: [First breakthrough marker — the earliest signal the channel has connected] | B40: No
A41: [Second breakthrough marker — a stronger confirmation of flow] | B41: No
A42: [Third breakthrough marker — the threshold you'd consider flow-mode achieved] | B42: No
A43: [Fourth marker — optional stretch target] | B43: No
...

Sheet Rewards
A1: REWARDS
A2: Customize the menu to match what you actually want — generic rewards don't motivate. Keep the three-tier structure (Recovery / Investment / Experience) and the currency split. Spending rewards is part of the system — don't hoard.
A4: REWARD MENU
A5: Category | B5: Reward | C5: Points Cost | D5: Digs Cost | E5: Requires Both? | F5: Notes
A6: Recovery | B6: [Your recovery reward — e.g. Movie evening] | C6: 30 | D6: 0 | F6: Customize name and cost
A7: Recovery | B7: [Your recovery reward — e.g. Favourite meal out] | C7: 50 | D7: 0
A8: Recovery | B8: [Your recovery reward — e.g. Half-day off-grid] | C8: 100 | D8: 0
A9: Recovery | B9: [Your recovery reward — e.g. Full rest day, no tracking] | C9: 150 | D9: 0
A10: Investment | B10: [Small tool / book / subscription — ≤$15] | C10: 0 | D10: 5
A11: Investment | B11: [Course or paid resource — $30–50] | C11: 0 | D11: 15
A12: Investment | B12: [Significant tool or equipment — $100+] | C12: 0 | D12: 30
A13: Experience | B13: [Day trip or local experience] | C13: 100 | D13: 20 | E13: Both | F13: Requires balanced output
A14: Experience | B14: [Weekend retreat or getaway] | C14: 200 | D14: 40 | E14: Both
A15: Experience | B15: [Significant trip or event] | C15: 500 | D15: 100 | E15: Both
A17: SPEND LOG
A18: Date | B18: Reward | C18: Category | D18: Notes | E18: Points Spent | F18: Digs Spent

Sheet Reference
A1: REFERENCE
A2: Point values, boost mechanics, channel taxonomy (fill yours in below). Re-read weekly — especially the drift columns.
A4: POINT VALUES
A5: Activity | B5: Points | C5: Digs | D5: Notes
A6: Dig block — 90 min phoneless, full artifact produced | B6: 10 | C6: 1.0 | D6: Multiplied by active boost stack
A7: Dig block — 90 min phoneless, no artifact produced | B7: 5 | C7: 0.5 | D7: Effort credit, half depth
A8: Extracurricular focused block (90 min) | B8: 5 | C8: 0 | D8: Non-channel learning, hobbies
A9: Gain action (Physical / Mental / Spiritual) | B9: 8 | C9: 0 | D9: + activates 1.5× boost for 24h
A10: Day Job hour | B10: 0 | C10: 0 | D10: Tracked for visibility — no inflation
A12: BOOST MECHANICS
A13: • Each gain action (Physical / Mental / Spiritual) activates a 1.5× point multiplier on dig blocks for 24h.
A14: • Boosts STACK ADDITIVELY: 1 active = 1.5× | 2 active = 2.0× | 3 active = 2.5×
A15: • 24h COOLDOWN per category after activation. To stack all three, invest across all three domains.
A16: • Apply the multiplier in the 'Boost Multiplier' column (col H) of Daily Log when logging dig blocks.
A17: • Dashboard shows live boost status (ACTIVE / READY) — check before logging a dig block.
A18: • Boosts reward the integrated person: training + deliberate learning + spiritual practice.
A20: GAIN ACTION DEFINITIONS (fill in your specifics)
A21: Physical Gain
A22: [List actions that qualify — e.g. 45-min workout, 5km run, yoga, cold shower]
A23: Mental Gain
A24: [List actions that qualify — e.g. deliberate vocabulary study, nonfiction reading with notes]
... A30: Channel 1
A31: DIGGING ✓ | C31: DRIFT ✗
A32: [Dig activity 1 — something that produces an artifact] | C32: [Drift activity 1 — feels like work, doesn't deepen channel]
A33: [Dig activity 2 — something that produces an artifact] | C33: [Drift activity 2 — feels like work, doesn't deepen channel]
A34: [Dig activity 3 — something that produces an artifact] | C34: [Drift activity 3 — feels like work, doesn't deepen channel]
A35: [Dig activity 4 — something that produces an artifact] | C35: [Drift activity 4 — feels like work, doesn't deepen channel]
A36: [Dig activity 5 — something that produces an artifact] | C36: [Drift activity 5 — feels like work, doesn't deepen channel]
A37: [Dig activity 6 — something that produces an artifact] | C37: [Drift activity 6 — feels like work, doesn't deepen channel]
A39: Channel 2
A40: DIGGING ✓ | C40: DRIFT ✗
A41: [Dig activity 1 — something that produces an artifact] | C41: [Drift activity 1 — feels like work, doesn't deepen channel]
A42: [Dig activity 2 — something that produces an artifact] | C42: [Drift activity 2 — feels like work, doesn't deepen channel]
A43: [Dig activity 3 — something that produces an artifact] | C43: [Drift activity 3 — feels like work, doesn't deepen channel]
A44: [Dig activity 4 — something that produces an artifact] | C44: [Drift activity 4 — feels like work, doesn't deepen channel]
A45: [Dig activity 5 — something that produces an artifact] | C45: [Drift activity 5 — feels like work, doesn't deepen channel]
A46: [Dig activity 6 — something that produces an artifact] | C46: [Drift activity 6 — feels like work, doesn't deepen channel]
A48: Channel 3
A49: DIGGING ✓ | C49: DRIFT ✗
A50: [Dig activity 1 — something that produces an artifact] | C50: [Drift activity 1 — feels like work, doesn't deepen channel]
...
